<mujoco model="dualarmhand0513">
  <option iterations="50" timestep="0.001" solver="PGS" gravity="0 0 -9.81" />

  <compiler angle="radian" meshdir="meshes" eulerseq="zyx" autolimits="true" />

  <default>
    <joint limited="true" damping="0.01" armature="0.01" frictionloss="0.01" />
    <geom condim="4" contype="1" conaffinity="15" friction="0.9 0.2 0.2" solref="0.001 2" />
    <motor ctrllimited="true" />
    <equality solref="0.001 2" />
    <default class="visualgeom">
      <geom material="visualgeom" condim="1" contype="0" conaffinity="0" />
    </default>
  </default>

  <asset>
    <mesh file="tabletop.stl" name="tabletop" scale="0.001 0.001 0.001"/>
    <mesh name="base_link" file="base_link.STL" />
    <mesh name="link0" file="link0.STL" />
    <mesh name="link1" file="link1.STL" />
    <mesh name="link2" file="link2.STL" />
    <mesh name="link3" file="link3.STL" />
    <mesh name="link4" file="link4.STL" />
    <mesh name="link5" file="link5.STL" />
    <mesh name="link6" file="link6.STL" />
    <mesh name="link7" file="link7.STL" />
    <mesh name="r_palm" file="r_palm.STL" />
    <mesh name="r_thumb0" file="r_thumb0.STL" />
    <mesh name="r_thumb1" file="r_thumb1.STL" />
    <mesh name="r_index0" file="r_index0.STL" />
    <mesh name="r_index1" file="r_index1.STL" />
    <mesh name="r_middle0" file="r_middle0.STL" />
    <mesh name="r_middle1" file="r_middle1.STL" />
    <mesh name="r_ring0" file="r_ring0.STL" />
    <mesh name="r_ring1" file="r_ring1.STL" />
    <mesh name="r_little0" file="r_little0.STL" />
    <mesh name="r_little1" file="r_little1.STL" />
    <mesh name="link0l" file="link0l.STL" />
    <mesh name="link1l" file="link1l.STL" />
    <mesh name="link2l" file="link2l.STL" />
    <mesh name="link3l" file="link3l.STL" />
    <mesh name="link4l" file="link4l.STL" />
    <mesh name="link5l" file="link5l.STL" />
    <mesh name="link6l" file="link6l.STL" />
    <mesh name="link7l" file="link7l.STL" />
    <mesh name="l_palm" file="l_palm.STL" />
    <mesh name="l_thumb0" file="l_thumb0.STL" />
    <mesh name="l_thumb1" file="l_thumb1.STL" />
    <mesh name="l_index0" file="l_index0.STL" />
    <mesh name="l_index1" file="l_index1.STL" />
    <mesh name="l_middle0" file="l_middle0.STL" />
    <mesh name="l_middle1" file="l_middle1.STL" />
    <mesh name="l_ring0" file="l_ring0.STL" />
    <mesh name="l_ring1" file="l_ring1.STL" />
    <mesh name="l_little0" file="l_little0.STL" />
    <mesh name="l_little1" file="l_little1.STL" />
    <material name="visualgeom" rgba="0.5 0.9 0.2 1" />
    <texture name="plane" type="2d" builtin="checker" rgb1=".2 .3 .4" rgb2=".1 0.15 0.2" width="512" height="512" mark="cross" markrgb=".8 .8 .8" />
    <material name="plane" reflectance="0.3" texture="plane" texrepeat="1 1" texuniform="true" />
  </asset>

  <!-- <visual> -->
  <!--     <map fogstart="1.5" fogend="5" force="0.1" znear="0.1"/> -->
  <!--     <quality shadowsize="4096" offsamples="4"/> -->
  <!--     <headlight ambient="0.4 0.4 0.4"/> -->
  <!-- </visual> -->

  <worldbody>
    <light directional="true" diffuse="0.4 0.4 0.4" specular="0.1 0.1 0.1" pos="0 0 5.0" dir="0 0 -1" castshadow="false" />
    <light directional="true" diffuse="0.6 0.6 0.6" specular="0.2 0.2 0.2" pos="0 0 4" dir="0 0 -1" />
    <geom name="ground" type="plane" pos="0 0 0" size="100 100 0.001" quat="1 0 0 0" material="plane" condim="3" conaffinity="15" />
    <camera name="fixed" pos="0.679 1.719 1.310" xyaxes="-0.819 0.574 -0.000 -0.241 -0.343 0.908"/>
    <camera name="track" mode="trackcom" pos="0 -3.0 0.4115608920854119" xyaxes="1 0 0 0 0 1" />
    

    <body name="root" pos="0 0 0" quat="1 0 0 0">
      <!-- <freejoint name="root" /> -->
      <site name="imu" size="0.01" pos="0 0 0" />
      <!-- <geom name="collision_0" pos="0 0 0.6" quat="1 0 0 0" type="mesh" rgba="0.75294 0.75294 0.75294 1" mesh="base_link" contype="1" conaffinity="0" density="0" group="1" class="visualgeom" /> -->
      <geom type="mesh" rgba="0.75294 0.75294 0.75294 1" mesh="base_link" pos="0 0 0.6" quat="1 0 0 0" group="0" contype="0" conaffinity="0" />
      <body name="link0" pos="0.1025 0 0.861">
        <camera name = "head" pos="-0.12 0.15 0.2" euler="0 0 0.4"/>
        <inertial pos="0.012169 0.0018303 -2.424e-05" quat="0.487168 0.512511 -0.487168 0.512511" mass="0.095121" diaginertia="5.2596e-05 5.05831e-05 3.84829e-05" />
        <joint name="joint0" pos="0 0 0" axis="0 0 1" range="-0.261799 0.523599" limited="true" frictionloss="1" />
        <geom name="collision_1" type="mesh" rgba="1 1 1 1" mesh="link0" contype="1" conaffinity="0" density="0" group="1" class="visualgeom" />
        <geom type="mesh" rgba="1 1 1 1" mesh="link0" />
        <body name="link1" pos="0.04525 0 0" quat="0.499998 0.5 0.500002 0.5">
          <inertial pos="0.0052443 0.00015497 0.044425" quat="0.673306 0.737953 -0.0341298 0.0303133" mass="0.23537" diaginertia="0.000240929 0.00022538 0.000151551" />
          <joint name="joint1" pos="0 0 0" axis="0 0 1" range="-0.523599 2.87979" limited="true" frictionloss="1" />
          <geom name="collision_2" type="mesh" rgba="1 1 1 1" mesh="link1" contype="1" conaffinity="0" density="0" group="1" class="visualgeom" />
          <geom type="mesh" rgba="1 1 1 1" mesh="link1" />
          <body name="link2" pos="0.001 0 0.0661" quat="0.499998 0.5 -0.500002 -0.5">
            <inertial pos="0.08948 0.00085362 0.0025442" quat="0.661324 0.749169 -0.00984587 0.0360406" mass="0.26937" diaginertia="0.000280271 0.00021769 0.000210339" />
            <joint name="joint2" pos="0 0 0" axis="0 0 1" range="-0.174533 2.35619" limited="true" frictionloss="1" />
            <geom name="collision_3" type="mesh" rgba="1 1 1 1" mesh="link2" contype="1" conaffinity="0" density="0" group="1" class="visualgeom" />
            <geom type="mesh" rgba="1 1 1 1" mesh="link2" />
            <body name="link3" pos="0.1535 0 0" quat="0.499998 -0.5 -0.500002 0.5">
              <inertial pos="-0.0014755 -0.0019094 -0.1014" quat="0.998423 -0.0560554 -0.00213098 -0.0019877" mass="0.099846" diaginertia="9.56926e-05 8.83572e-05 6.80622e-05" />
              <joint name="joint3" pos="0 0 0" axis="0 0 1" range="-0.261799 1.5708" limited="true" frictionloss="1" />
              <geom name="collision_4" type="mesh" rgba="1 1 1 1" mesh="link3" contype="1" conaffinity="0" density="0" group="1" class="visualgeom" />
              <geom type="mesh" rgba="1 1 1 1" mesh="link3" />
              <body name="link4" pos="4.967e-05 -0.002 -0.1565" quat="0.499998 -0.5 0.500002 -0.5">
                <inertial pos="0.001862 0.060603 -0.00066615" quat="0.941162 -0.0104913 -0.00601835 0.33774" mass="0.09046" diaginertia="4.64824e-05 4.09404e-05 3.63792e-05" />
                <joint name="joint4" pos="0 0 0" axis="0 0 1" range="0 2.35619" limited="true" frictionloss="1" />
                <geom name="collision_5" type="mesh" rgba="1 1 1 1" mesh="link4" contype="1" conaffinity="0" density="0" group="1" class="visualgeom" />
                <geom type="mesh" rgba="1 1 1 1" mesh="link4" />
                <body name="link5" pos="-0.006 0.10035 0" quat="0.707105 -0.707108 0 0">
                  <camera name="wrist_cam" pos="0 0.15 0.04" euler="0 0 -2.9"/>

                  <inertial pos="2.5647e-05 -0.0015367 0.05438" quat="0.706178 0.00524261 -0.00164221 0.708013" mass="0.089997" diaginertia="9.08701e-05 8.97511e-05 4.80539e-05" />
                  <joint name="joint5" pos="0 0 0" axis="0 0 1" range="-1.0472 1.5708" limited="true" frictionloss="1" />
                  <geom name="collision_6" type="mesh" rgba="1 1 1 1" mesh="link5" contype="1" conaffinity="0" density="0" group="1" class="visualgeom" />
                  <geom type="mesh" rgba="1 1 1 1" mesh="link5" />
                  <body name="link6" pos="0 0 0.147" quat="0.707105 -0.707108 0 0">
                    <inertial pos="-0.0058503 -0.00043597 -0.0001607" quat="0.999907 -0.0136336 6.05158e-05 -0.000155387" mass="0.02139" diaginertia="3.9115e-06 2.37927e-06 2.01013e-06" />
                    <joint name="joint6" pos="0 0 0" axis="0 0 1" range="-0.349066 1.0472" limited="true" frictionloss="1" />
                    <geom name="collision_7" type="mesh" rgba="1 1 1 1" mesh="link6" contype="1" conaffinity="0" density="0" group="1" class="visualgeom" />
                    <geom type="mesh" rgba="1 1 1 1" mesh="link6" />
                    <body name="link7" pos="0.0002 0 0" quat="0.499998 0.5 -0.500002 -0.5">
                      <inertial pos="0.0729747 -0.00560062 -0.00450405" quat="0.499216 0.534161 0.478692 0.486117" mass="0.16935" diaginertia="0.000210927 0.000145719 7.79658e-05" />
                      <joint name="joint7" pos="0 0 0" axis="0 0 1" range="-1.0472 1.0472" limited="true" frictionloss="1" />
                      <geom name="collision_8" type="mesh" rgba="1 1 1 1" mesh="link7" contype="1" conaffinity="0" density="0" group="1" class="visualgeom" />
                      <geom type="mesh" rgba="1 1 1 1" mesh="link7" />
                      <geom name="collision_9" pos="0.0255 0 0" quat="1 0 0 0" type="mesh" rgba="1 1 1 1" mesh="r_palm" contype="1" conaffinity="0" density="0" group="1" class="visualgeom" />
                      <geom type="mesh" rgba="1 1 1 1" mesh="r_palm" pos="0.0255 0 0" quat="1 0 0 0" />
                      <body name="r_thumb0" pos="0.063456 0.00059154 0.031804" quat="0.41444 0.57292 -0.572922 -0.414441">
                        <inertial pos="-0.0025038 0.0064489 -0.003" quat="0.693922 0.693922 0.135911 0.135911" mass="0.00080239" diaginertia="2.67195e-08 2.4013e-08 1.02455e-08" />
                        <joint name="r_t0" pos="0 0 0" axis="0 0 1" range="-3.1416 3.1416" limited="true" frictionloss="1" />
                        <geom name="collision_10" type="mesh" rgba="1 1 1 1" mesh="r_thumb0" contype="1" conaffinity="0" density="0" group="1" class="visualgeom" />
                        <geom type="mesh" rgba="1 1 1 1" mesh="r_thumb0" />
                        <body name="r_thumb1" pos="-0.0091806 0.0064783 -0.003" quat="0.418237 0.686847 -0.16794 -0.570188">
                          <inertial pos="-0.0083415 -0.03781 -0.0028707" quat="0.733937 0.455356 -0.229144 0.448866" mass="0.025362" diaginertia="6.17005e-06 5.73982e-06 1.98952e-06" />
                          <joint name="r_t1" pos="0 0 0" axis="8.5042e-05 0 1" range="-3.1416 3.1416" limited="true" frictionloss="1" />
                          <geom name="collision_11" type="mesh" rgba="1 1 1 1" mesh="r_thumb1" contype="1" conaffinity="0" density="0" group="1" class="visualgeom" />
                          <geom type="mesh" rgba="1 1 1 1" mesh="r_thumb1" />
                        </body>
                      </body>
                      <body name="r_index0" pos="0.12573 -0.0063084 0.031221" quat="0.0153229 0.839319 0.542907 0.0237006">
                        <inertial pos="0.011082 0.0143 0.0040069" quat="0.649298 0.2835 -0.648201 0.27906" mass="0.0062523" diaginertia="1.0004e-06 9.81294e-07 3.26584e-07" />
                        <joint name="r_i0" pos="0 0 0" axis="0 0 -1" range="-3.1416 3.1416" limited="true" frictionloss="1" />
                        <geom name="collision_12" type="mesh" rgba="1 1 1 1" mesh="r_index0" contype="1" conaffinity="0" density="0" group="1" class="visualgeom" />
                        <geom type="mesh" rgba="1 1 1 1" mesh="r_index0" />
                        <body name="r_index1" pos="0.025456 0.031113 0.00010065" quat="0.985296 0 0 -0.170858">
                          <inertial pos="0.015022 0.015336 0.0038982" quat="0.653411 0.653976 -0.268955 -0.270245" mass="0.0064216" diaginertia="7.071e-07 6.7773e-07 1.5521e-07" />
                          <joint name="r_i1" pos="0 0 0" axis="0 0 -1" range="-3.1416 3.1416" limited="true" frictionloss="1" />
                          <geom name="collision_13" type="mesh" rgba="1 1 1 1" mesh="r_index1" contype="1" conaffinity="0" density="0" group="1" class="visualgeom" />
                          <geom type="mesh" rgba="1 1 1 1" mesh="r_index1" />
                        </body>
                      </body>
                      <body name="r_middle0" pos="0.12951 -0.0094084 0.0083636" quat="0.0047825 -0.834963 -0.550237 0.0072743">
                        <inertial pos="0.011082 0.0143 0.0040069" quat="0.649298 0.283503 -0.6482 0.279062" mass="0.0062523" diaginertia="1.0004e-06 9.81299e-07 3.26589e-07" />
                        <joint name="r_m0" pos="0 0 0" axis="0 0 -1" range="-3.1416 3.1416" limited="true" frictionloss="1" />
                        <geom name="collision_14" type="mesh" rgba="1 1 1 1" mesh="r_middle0" contype="1" conaffinity="0" density="0" group="1" class="visualgeom" />
                        <geom type="mesh" rgba="1 1 1 1" mesh="r_middle0" />
                        <body name="r_middle1" pos="0.025456 0.031113 0.00010065" quat="0.984691 0 0 -0.17431">
                          <inertial pos="0.014462 0.014705 0.0039096" quat="0.275958 0.27461 0.65126 0.651381" mass="0.005651" diaginertia="7.75575e-07 7.4638e-07 1.45955e-07" />
                          <joint name="r_m1" pos="0 0 0" axis="0 0 -1" range="-3.1416 3.1416" limited="true" frictionloss="1" />
                          <geom name="collision_15" type="mesh" rgba="1 1 1 1" mesh="r_middle1" contype="1" conaffinity="0" density="0" group="1" class="visualgeom" />
                          <geom type="mesh" rgba="1 1 1 1" mesh="r_middle1" />
                        </body>
                      </body>
                      <body name="r_ring0" pos="0.12737 -0.0094084 -0.014412" quat="0.0244067 -0.834193 -0.549685 0.0370507">
                        <inertial pos="0.011082 0.0143 0.004007" quat="0.649296 0.283498 -0.648203 0.279062" mass="0.0062524" diaginertia="1.0004e-06 9.81314e-07 3.26584e-07" />
                        <joint name="r_r0" pos="0 0 0" axis="0 0 -1" range="-3.1416 3.1416" limited="true" frictionloss="1" />
                        <geom name="collision_16" type="mesh" rgba="1 1 1 1" mesh="r_ring0" contype="1" conaffinity="0" density="0" group="1" class="visualgeom" />
                        <geom type="mesh" rgba="1 1 1 1" mesh="r_ring0" />
                        <body name="r_ring1" pos="0.025456 0.031113 0.00010065" quat="0.984331 0 0 -0.176328">
                          <inertial pos="0.014648 0.014799 0.0038983" quat="0.275441 0.274514 0.651614 0.651286" mass="0.0060049" diaginertia="6.71229e-07 6.4199e-07 1.51701e-07" />
                          <joint name="r_r1" pos="0 0 0" axis="0 0 -1" range="-3.1416 3.1416" limited="true" frictionloss="1" />
                          <geom name="collision_17" type="mesh" rgba="1 1 1 1" mesh="r_ring1" contype="1" conaffinity="0" density="0" group="1" class="visualgeom" />
                          <geom type="mesh" rgba="1 1 1 1" mesh="r_ring1" />
                        </body>
                      </body>
                      <body name="r_little0" pos="0.120279 -0.0064084 -0.036859" quat="0.0518388 -0.836155 -0.54011 0.0802438">
                        <inertial pos="0.011082 0.0143 0.0040069" quat="0.649298 0.283503 -0.6482 0.279062" mass="0.0062523" diaginertia="1.0004e-06 9.81299e-07 3.26589e-07" />
                        <joint name="r_l0" pos="0 0 0" axis="0 0 -1" range="-3.1416 3.1416" limited="true" frictionloss="1" />
                        <geom name="collision_18" type="mesh" rgba="1 1 1 1" mesh="r_little0" contype="1" conaffinity="0" density="0" group="1" class="visualgeom" />
                        <geom type="mesh" rgba="1 1 1 1" mesh="r_little0" />
                        <body name="r_little1" pos="0.025456 0.031113 0.00010065" quat="0.984655 0 0 -0.174512">
                          <inertial pos="0.012116 0.012914 0.0038963" quat="0.655174 0.653469 -0.270892 -0.265222" mass="0.0046442" diaginertia="4.1198e-07 3.94109e-07 1.04401e-07" />
                          <joint name="r_l1" pos="0 0 0" axis="0 0 -1" range="-3.1416 3.1416" limited="true" frictionloss="1" />
                          <geom name="collision_19" type="mesh" rgba="1 1 1 1" mesh="r_little1" contype="1" conaffinity="0" density="0" group="1" class="visualgeom" />
                          <geom type="mesh" rgba="1 1 1 1" mesh="r_little1" />
                        </body>
                      </body>
                    </body>
                  </body>
                </body>
              </body>
            </body>
          </body>
        </body>
      </body>
      <body name="link0l" pos="-0.1025 0 0.861" quat="-3.67321e-06 0 0 -1">
        <inertial pos="0.012169 0.0018303 -2.424e-05" quat="0.487168 0.512511 -0.487168 0.512511" mass="0.095121" diaginertia="5.2596e-05 5.05831e-05 3.84829e-05" />
        <joint name="joint0l" pos="0 0 0" axis="0 0 1" range="-0.523599 0.261799" limited="true" frictionloss="1" />
        <geom name="collision_20" type="mesh" rgba="1 1 1 1" mesh="link0l" contype="1" conaffinity="0" density="0" group="1" class="visualgeom" />
        <geom type="mesh" rgba="1 1 1 1" mesh="link0l" />
        <body name="link1l" pos="0.04525 0 0" quat="0.499998 0.5 0.500002 0.5">
          <inertial pos="0.0052443 0.00015497 0.044425" quat="0.673306 0.737953 -0.0341297 0.0303133" mass="0.23537" diaginertia="0.000240929 0.00022538 0.000151551" />
          <joint name="joint1l" pos="0 0 0" axis="0 0 1" range="-2.87979 0.523599" limited="true" frictionloss="1" />
          <geom name="collision_21" type="mesh" rgba="1 1 1 1" mesh="link1l" contype="1" conaffinity="0" density="0" group="1" class="visualgeom" />
          <geom type="mesh" rgba="1 1 1 1" mesh="link1l" />
          <body name="link2l" pos="0.001 0 0.0661" quat="0.499998 0.5 -0.500002 -0.5">
            <inertial pos="0.08948 0.00085362 0.0025442" quat="0.661324 0.749169 -0.00984587 0.0360406" mass="0.26937" diaginertia="0.000280271 0.00021769 0.000210339" />
            <joint name="joint2l" pos="0 0 0" axis="0 0 1" range="-0.174533 2.35619" limited="true" frictionloss="1" />
            <geom name="collision_22" type="mesh" rgba="1 1 1 1" mesh="link2l" contype="1" conaffinity="0" density="0" group="1" class="visualgeom" />
            <geom type="mesh" rgba="1 1 1 1" mesh="link2l" />
            <body name="link3l" pos="0.1535 0 0" quat="0.499998 -0.5 -0.500002 0.5">
              <inertial pos="0.0014755 0.0019094 -0.1014" quat="0.998423 0.0560554 0.00213098 -0.0019877" mass="0.099846" diaginertia="9.56926e-05 8.83572e-05 6.80622e-05" />
              <joint name="joint3l" pos="0 0 0" axis="0 0 1" range="-1.5708 1.5708" limited="true" frictionloss="1" />
              <geom name="collision_23" type="mesh" rgba="1 1 1 1" mesh="link3l" contype="1" conaffinity="0" density="0" group="1" class="visualgeom" />
              <geom type="mesh" rgba="1 1 1 1" mesh="link3l" />
              <body name="link4l" pos="-4.967e-05 0.002 -0.1565" quat="0.499998 -0.5 0.500002 -0.5">
                <inertial pos="-0.001862 0.060603 0.00066615" quat="0.941162 0.0104913 -0.00601835 -0.33774" mass="0.09046" diaginertia="4.64824e-05 4.09404e-05 3.63792e-05" />
                <joint name="joint4l" pos="0 0 0" axis="0 0 1" range="-2.35619 0" limited="true" frictionloss="1" />
                <geom name="collision_24" type="mesh" rgba="1 1 1 1" mesh="link4l" contype="1" conaffinity="0" density="0" group="1" class="visualgeom" />
                <geom type="mesh" rgba="1 1 1 1" mesh="link4l" />
                <body name="link5l" pos="0.006 0.10035 0" quat="0.707105 -0.707108 0 0">
                  <inertial pos="2.5647e-05 -0.0015367 0.05438" quat="0.706178 0.00524261 -0.00164221 0.708013" mass="0.089997" diaginertia="9.08701e-05 8.97511e-05 4.80539e-05" />
                  <joint name="joint5l" pos="0 0 0" axis="0 0 1" range="-1.5708 1.5708" limited="true" frictionloss="1" />
                  <geom name="collision_25" type="mesh" rgba="1 1 1 1" mesh="link5l" contype="1" conaffinity="0" density="0" group="1" class="visualgeom" />
                  <geom type="mesh" rgba="1 1 1 1" mesh="link5l" />
                  <body name="link6l" pos="0 0 0.147" quat="0.707105 -0.707108 0 0">
                    <inertial pos="-0.0058503 -0.00043597 -0.0001607" quat="0.999907 -0.0136336 6.05158e-05 -0.000155387" mass="0.02139" diaginertia="3.9115e-06 2.37927e-06 2.01013e-06" />
                    <joint name="joint6l" pos="0 0 0" axis="0 0 1" range="-1.5708 1.5708" limited="true" frictionloss="1" />
                    <geom name="collision_26" type="mesh" rgba="1 1 1 1" mesh="link6l" contype="1" conaffinity="0" density="0" group="1" class="visualgeom" />
                    <geom type="mesh" rgba="1 1 1 1" mesh="link6l" />
                    <body name="link7l" pos="0.0002 0 0" quat="0.499998 0.5 -0.500002 -0.5">
                      <inertial pos="0.0683902 -0.00560253 0.00439997" quat="0.537719 0.495773 0.482299 0.482136" mass="0.16935" diaginertia="0.000207139 0.000141849 7.80773e-05" />
                      <joint name="joint7l" pos="0 0 0" axis="0 0 1" range="-1.5708 1.5708" limited="true" frictionloss="1" />
                      <geom name="collision_27" type="mesh" rgba="1 1 1 1" mesh="link7l" contype="1" conaffinity="0" density="0" group="1" class="visualgeom" />
                      <geom type="mesh" rgba="1 1 1 1" mesh="link7l" />
                      <geom name="collision_28" pos="0.0255 0 0" quat="1 0 0 0" type="mesh" rgba="1 1 1 1" mesh="l_palm" contype="1" conaffinity="0" density="0" group="1" class="visualgeom" />
                      <geom type="mesh" rgba="1 1 1 1" mesh="l_palm" pos="0.0255 0 0" quat="1 0 0 0" />
                      <body name="l_thumb0" pos="0.058608 0.00059156 -0.031789" quat="0.41444 -0.57292 0.572922 -0.414441">
                        <inertial pos="-0.0025024 0.0064494 0.003" quat="0.693935 0.693935 0.135844 0.135844" mass="0.00080239" diaginertia="2.67192e-08 2.4013e-08 1.02458e-08" />
                        <joint name="l_t0" pos="0 0 0" axis="0 0 1" range="-3.1416 3.1416" limited="true" frictionloss="1" />
                        <geom name="collision_29" type="mesh" rgba="1 1 1 1" mesh="l_thumb0" contype="1" conaffinity="0" density="0" group="1" class="visualgeom" />
                        <geom type="mesh" rgba="1 1 1 1" mesh="l_thumb0" />
                        <body name="l_thumb1" pos="-0.0091791 0.0064802 0.003" quat="0.587956 -0.587958 0.39282 -0.392818">
                          <inertial pos="-0.030696 -0.023604 0.0028663" quat="0.371003 0.170666 -0.843244 0.349528" mass="0.025364" diaginertia="6.17185e-06 5.7416e-06 1.98965e-06" />
                          <joint name="l_t1" pos="0 0 0" axis="0 0 1" range="-3.1416 3.1416" limited="true" frictionloss="1" />
                          <geom name="collision_30" type="mesh" rgba="1 1 1 1" mesh="l_thumb1" contype="1" conaffinity="0" density="0" group="1" class="visualgeom" />
                          <geom type="mesh" rgba="1 1 1 1" mesh="l_thumb1" />
                        </body>
                      </body>
                      <body name="l_index0" pos="0.12093 -0.0063084 -0.031221" quat="0.706824 -0.0199646 0.0199647 -0.706826">
                        <inertial pos="-0.0043905 0.01755 0.0040066" quat="0.40639 0.575924 -0.410906 0.5782" mass="0.0062519" diaginertia="1.0003e-06 9.81208e-07 3.26551e-07" />
                        <joint name="l_i0" pos="0 0 0" axis="0 0 1" range="-3.1416 3.1416" limited="true" frictionloss="1" />
                        <geom name="collision_31" type="mesh" rgba="1 1 1 1" mesh="l_index0" contype="1" conaffinity="0" density="0" group="1" class="visualgeom" />
                        <geom type="mesh" rgba="1 1 1 1" mesh="l_index0" />
                        <body name="l_index1" pos="-0.010785 0.038726 0.00010065">
                          <inertial pos="-0.014554 0.015783 0.0038977" quat="0.657387 0.657987 0.258956 0.260456" mass="0.0064217" diaginertia="7.0718e-07 6.7782e-07 1.55201e-07" />
                          <joint name="l_i1" pos="0 0 0" axis="0 0 1" range="-3.1416 3.1416" limited="true" frictionloss="1" />
                          <geom name="collision_32" type="mesh" rgba="1 1 1 1" mesh="l_index1" contype="1" conaffinity="0" density="0" group="1" class="visualgeom" />
                          <geom type="mesh" rgba="1 1 1 1" mesh="l_index1" />
                        </body>
                      </body>
                      <body name="l_middle0" pos="0.12471 -0.0094084 -0.0083636" quat="0.707079 0.00617048 -0.0061705 -0.707081">
                        <inertial pos="-0.0045119 0.017519 0.0040067" quat="0.404382 0.57734 -0.408918 0.579603" mass="0.0062519" diaginertia="1.0003e-06 9.81208e-07 3.2655e-07" />
                        <joint name="l_m0" pos="0 0 0" axis="0 0 1" range="-3.1416 3.1416" limited="true" frictionloss="1" />
                        <geom name="collision_33" type="mesh" rgba="1 1 1 1" mesh="l_middle0" contype="1" conaffinity="0" density="0" group="1" class="visualgeom" />
                        <geom type="mesh" rgba="1 1 1 1" mesh="l_middle0" />
                        <body name="l_middle1" pos="-0.011053 0.03865 0.00010065">
                          <inertial pos="-0.01382 0.015312 0.0039095" quat="0.657008 0.657118 0.261985 0.260575" mass="0.005651" diaginertia="7.75609e-07 7.4641e-07 1.4595e-07" />
                          <joint name="l_m1" pos="0 0 0" axis="0 0 1" range="-3.1416 3.1416" limited="true" frictionloss="1" />
                          <geom name="collision_34" type="mesh" rgba="1 1 1 1" mesh="l_middle1" contype="1" conaffinity="0" density="0" group="1" class="visualgeom" />
                          <geom type="mesh" rgba="1 1 1 1" mesh="l_middle1" />
                        </body>
                      </body>
                      <body name="l_ring0" pos="0.12257 -0.0094084 0.014412" quat="0.706409 0.0313852 -0.0313853 -0.706411">
                        <inertial pos="-0.0046704 0.017477 0.0040067" quat="0.401743 0.579181 -0.406309 0.581433" mass="0.0062519" diaginertia="1.0003e-06 9.81219e-07 3.2655e-07" />
                        <joint name="l_r0" pos="0 0 0" axis="0 0 1" range="-3.1416 3.1416" limited="true" frictionloss="1" />
                        <geom name="collision_35" type="mesh" rgba="1 1 1 1" mesh="l_ring0" contype="1" conaffinity="0" density="0" group="1" class="visualgeom" />
                        <geom type="mesh" rgba="1 1 1 1" mesh="l_ring0" />
                        <body name="l_ring1" pos="-0.011402 0.038548 0.00010065">
                          <inertial pos="-0.014063 0.015356 0.0038992" quat="0.656856 0.656413 0.262976 0.261735" mass="0.0060041" diaginertia="6.71414e-07 6.422e-07 1.51696e-07" />
                          <joint name="l_r1" pos="0 0 0" axis="0 0 1" range="-3.1416 3.1416" limited="true" frictionloss="1" />
                          <geom name="collision_36" type="mesh" rgba="1 1 1 1" mesh="l_ring1" contype="1" conaffinity="0" density="0" group="1" class="visualgeom" />
                          <geom type="mesh" rgba="1 1 1 1" mesh="l_ring1" />
                        </body>
                      </body>
                      <body name="l_little0" pos="0.115479 -0.0064084 0.036859" quat="0.703872 0.0675492 -0.0675494 -0.703874">
                        <inertial pos="-0.0048622 0.017425 0.0040067" quat="0.398546 0.581411 -0.403109 0.583631" mass="0.0062519" diaginertia="1.0003e-06 9.81205e-07 3.26553e-07" />
                        <joint name="l_l0" pos="0 0 0" axis="0 0 1" range="-3.1416 3.1416" limited="true" frictionloss="1" />
                        <geom name="collision_37" type="mesh" rgba="1 1 1 1" mesh="l_little0" contype="1" conaffinity="0" density="0" group="1" class="visualgeom" />
                        <geom type="mesh" rgba="1 1 1 1" mesh="l_little0" />
                        <body name="l_little1" pos="-0.011825 0.038421 0.00010065">
                          <inertial pos="-0.011652 0.013331 0.0038963" quat="0.659673 0.658206 0.259193 0.2538" mass="0.0046444" diaginertia="4.11919e-07 3.94049e-07 1.04422e-07" />
                          <joint name="l_l1" pos="0 0 0" axis="0 0 1" range="-3.1416 3.1416" limited="true" frictionloss="1" />
                          <geom name="collision_38" type="mesh" rgba="1 1 1 1" mesh="l_little1" contype="1" conaffinity="0" density="0" group="1" class="visualgeom" />
                          <geom type="mesh" rgba="1 1 1 1" mesh="l_little1" />
                        </body>
                      </body>
                    </body>
                  </body>
                </body>
              </body>
            </body>
          </body>
        </body>
      </body>
    </body>

    <body name="table" pos="0 1 0">
      <geom group="1" mesh="tabletop" pos="0 0 0.4" type="mesh" conaffinity="1" contype="1" name="table" rgba="0.2 0.2 0.2 1" />
    </body>
    <body name="target_box" pos="0 1 0.2">
      <joint name="box_joint" type="free" frictionloss="0.01" />
      <inertial pos="0 0 0" mass="0.05" diaginertia="0.002 0.002 0.002" />
      <geom pos="0 0 0.24" size="0.03 0.03 0.03" type="box" name="target_box" rgba="1 0 0 1"/>
    </body>
    
  </worldbody>

  <actuator>
    <position name="joint0" joint="joint0" kp="100" ctrlrange="-3.14 3.14" forcerange="-20 20"/>
    <position name="joint1" joint="joint1" kp="100" ctrlrange="-3.14 3.14" forcerange="-20 20"/>
    <position name="joint2" joint="joint2" kp="100" ctrlrange="-3.14 3.14" forcerange="-20 20"/>
    <position name="joint3" joint="joint3" kp="100" ctrlrange="-3.14 3.14" forcerange="-20 20"/>
    <position name="joint4" joint="joint4" kp="100" ctrlrange="-3.14 3.14" forcerange="-20 20"/>
    <position name="joint5" joint="joint5" kp="100" ctrlrange="-3.14 3.14" forcerange="-20 20"/>
    <position name="joint6" joint="joint6" kp="100" ctrlrange="-3.14 3.14" forcerange="-20 20"/>
    <position name="joint7" joint="joint7" kp="100" ctrlrange="-3.14 3.14" forcerange="-20 20"/>
    <position name="r_t0" joint="r_t0" kp="100" ctrlrange="-3.14 3.14" forcerange="-20 20"/>
    <position name="r_t1" joint="r_t1" kp="100" ctrlrange="-3.14 3.14" forcerange="-20 20"/>
    <position name="r_i0" joint="r_i0" kp="100" ctrlrange="-3.14 3.14" forcerange="-20 20"/>
    <position name="r_i1" joint="r_i1" kp="100" ctrlrange="-3.14 3.14" forcerange="-20 20"/>
    <position name="r_m0" joint="r_m0" kp="100" ctrlrange="-3.14 3.14" forcerange="-20 20"/>
    <position name="r_m1" joint="r_m1" kp="100" ctrlrange="-3.14 3.14" forcerange="-20 20"/>
    <position name="r_r0" joint="r_r0" kp="100" ctrlrange="-3.14 3.14" forcerange="-20 20"/>
    <position name="r_r1" joint="r_r1" kp="100" ctrlrange="-3.14 3.14" forcerange="-20 20"/>
    <position name="r_l0" joint="r_l0" kp="100" ctrlrange="-3.14 3.14" forcerange="-20 20"/>
    <position name="r_l1" joint="r_l1" kp="100" ctrlrange="-3.14 3.14" forcerange="-20 20"/>
    <position name="joint0l" joint="joint0l" kp="100" ctrlrange="-3.14 3.14" forcerange="-20 20"/>
    <position name="joint1l" joint="joint1l" kp="100" ctrlrange="-3.14 3.14" forcerange="-20 20"/>
    <position name="joint2l" joint="joint2l" kp="100" ctrlrange="-3.14 3.14" forcerange="-20 20"/>
    <position name="joint3l" joint="joint3l" kp="100" ctrlrange="-3.14 3.14" forcerange="-20 20"/>
    <position name="joint4l" joint="joint4l" kp="100" ctrlrange="-3.14 3.14" forcerange="-20 20"/>
    <position name="joint5l" joint="joint5l" kp="100" ctrlrange="-3.14 3.14" forcerange="-20 20"/>
    <position name="joint6l" joint="joint6l" kp="100" ctrlrange="-3.14 3.14" forcerange="-20 20"/>
    <position name="joint7l" joint="joint7l" kp="100" ctrlrange="-3.14 3.14" forcerange="-20 20"/>
    <position name="l_t0" joint="l_t0" kp="100" ctrlrange="-3.14 3.14" forcerange="-20 20"/>
    <position name="l_t1" joint="l_t1" kp="100" ctrlrange="-3.14 3.14" forcerange="-20 20"/>
    <position name="l_i0" joint="l_i0" kp="100" ctrlrange="-3.14 3.14" forcerange="-20 20"/>
    <position name="l_i1" joint="l_i1" kp="100" ctrlrange="-3.14 3.14" forcerange="-20 20"/>
    <position name="l_m0" joint="l_m0" kp="100" ctrlrange="-3.14 3.14" forcerange="-20 20"/>
    <position name="l_m1" joint="l_m1" kp="100" ctrlrange="-3.14 3.14" forcerange="-20 20"/>
    <position name="l_r0" joint="l_r0" kp="100" ctrlrange="-3.14 3.14" forcerange="-20 20"/>
    <position name="l_r1" joint="l_r1" kp="100" ctrlrange="-3.14 3.14" forcerange="-20 20"/>
    <position name="l_l0" joint="l_l0" kp="100" ctrlrange="-3.14 3.14" forcerange="-20 20"/>
    <position name="l_l1" joint="l_l1" kp="100" ctrlrange="-3.14 3.14" forcerange="-20 20"/>
  </actuator> 
  
</mujoco>
